<?xml version="1.0" ?>
<robot name="H6_robot">

  <link name="head">
     <visual>
      <geometry>
        <mesh filename="meshes/Head_0.10.stl" scale="0.1 0.1 0.1"/>
      </geometry>
      <origin rpy="0 0 3.14" xyz="0  10 -0.006"/>
    </visual>
    <collision>
      <geometry>
        <mesh filename="meshes/Head_0.10.stl" scale="0.1 0.1 0.1"/>
      </geometry>
      <origin rpy="0 0 0" xyz="0 -0.055 -0.01"/>
    </collision>
  </link>

  <joint name="head_to_neck" type="revolute">
    <parent link="head"/>
    <child link="neck"/>
    <origin rpy="0 0 0" xyz="0  0  0"/>
    <axis xyz="1.0 0 0"/>
    <limit effort="1.329" lower="-0.2626" upper="0.5252" velocity="8.26797"/>
  </joint>

  <link name="neck">
     <visual>
      <geometry>
        <mesh filename="meshes/Neck_0.10.stl" scale="0.1 0.1 0.1"/>
      </geometry>
      <origin rpy="0 0 0" xyz="0  0  0"/>
    </visual>
    <collision>
      <geometry>
        <mesh filename="meshes/Neck_0.10.stl" scale="0.1 0.1 0.1"/>
      </geometry>
      <origin rpy="0 0 0" xyz="0  0  0"/>
    </collision>
  </link>


  <joint name="neck_to_torso" type="revolute">
    <parent link="neck"/>
    <child link="torso"/>
    <origin rpy="0 0 0" xyz="0  0  0"/>
    <axis xyz="0 1.0 0"/>
    <limit effort="1.329" lower="-1.5757" upper="1.5757" velocity="8.26797"/>
  </joint>


  <link name="torso">
    <visual>
      <geometry>
        <mesh filename="meshes/Torso_0.10.stl" scale="0.1 0.1 0.1"/>
      </geometry>
      <origin rpy="0 0 0" xyz="0 0 0"/>
    </visual>
    <collision>
      <geometry>
        <mesh filename="meshes/Torso_0.10.stl" scale="0.1 0.1 0.1"/>
      </geometry>
      <origin rpy="0 0 0" xyz="0 0 0"/>
    </collision>
  </link>


   <joint name="LShoulderPitch" type="revolute">
    <parent link="torso"/>
    <child link="LShoulder"/>
    <origin rpy="0 0 0" xyz="0.05 0.0 0.006"/>
    <axis xyz="1.0 0 0"/>
    <limit effort="1.329" lower="-3.1415" upper="1.0471" velocity="8.26797"/>
  </joint>

  <link name="LShoulder">
     <visual>
      <geometry>
        <mesh filename="meshes/LShoulderPitch_0.10.stl" scale="0.1 0.1 0.1"/>
      </geometry>
      <origin rpy="0 0 0" xyz="-0.05 0 -0.006"/>
    </visual>
    <collision>
      <geometry>
        <mesh filename="meshes/LShoulderPitch_0.10.stl" scale="0.1 0.1 0.1"/>
      </geometry>
      <origin rpy="0 0 0" xyz="-0.05 0 -0.006"/>
    </collision>
  </link>

  <joint name="LShoulderRoll" type="revolute">
    <parent link="LShoulder"/>
    <child link="LBicep"/>
    <origin rpy="0 0 0" xyz="0.04 0.0 0.0"/>
    <axis xyz="0 0 1.0"/>
    <limit effort="1.329" lower="-1.5757" upper="1.5757" velocity="8.26797"/>
  </joint>

  <link name="LBicep">
     <visual>
      <geometry>
        <mesh filename="meshes/LShoulderRoll_0.10.stl" scale="0.1 0.1 0.1"/>
      </geometry>
      <origin rpy="0 0 0" xyz="-0.09 0 -0.006"/>
    </visual>
    <collision>
      <geometry>
        <mesh filename="meshes/LShoulderRoll_0.10.stl" scale="0.1 0.1 0.1"/>
      </geometry>
      <origin rpy="0 0 0" xyz="-0.09 0 -0.006"/>
    </collision>
  </link>

  <joint name="LElbowYaw" type="revolute">
    <parent link="LBicep"/>
    <child link="LElbow"/>
    <origin rpy="0 0 0" xyz="0 0.0 0.0"/>
    <limit effort="1.329" lower="-1.5757" upper="1.5757" velocity="8.26797"/>
  </joint>

  <link name="LElbow">
     <visual>
      <geometry>
        <mesh filename="meshes/LElbow_0.10.stl" scale="0.1 0.1 0.1"/>
      </geometry>
      <origin rpy="0 -1.57 0" xyz="0 0 0"/>
    </visual>
    <collision>
      <geometry>
        <mesh filename="meshes/LElbow_0.10.stl" scale="0.1 0.1 0.1"/>
      </geometry>
      <origin rpy="0 -1.57 0" xyz="0 0 0"/>
    </collision>
  </link>

  <joint name="LHipYaw" type="revolute">
    <parent link="torso"/>
    <child link="LHipYaw"/>
    <origin rpy="-1.5757 0.0 3.14159" xyz="0.035 -0.035 0.0"/>
    <axis xyz="0 0 1.0"/>
    <limit effort="1.329" lower="-1.5757" upper="1.5757" velocity="8.26797"/>
  </joint>

  <link name="LHipYaw">
     <visual>
      <geometry>
        <mesh filename="meshes/LHipYaw_0.10.stl" scale="0.1 0.1 0.1"/>
      </geometry>
      <origin rpy="1.57 3.14 0" xyz="4 -4 0"/>
    </visual>
    <collision>
      <geometry>
        <mesh filename="meshes/LHipYaw_0.10.stl" scale="0.1 0.1 0.1"/>
      </geometry>
      <origin rpy="0 0 0" xyz="0.0 0.0 0.0"/>
    </collision>
  </link>

  <joint name="LHipRoll" type="revolute">
    <parent link="LHipYaw"/>
    <child link="LHipRoll"/>
    <origin rpy="1.5757 3.14159 0.0" xyz="0.0 0.0 0.09"/>
    <axis xyz="0 0 1.0"/>
    <limit effort="1.329" lower="-0.45" upper="1.5757" velocity="8.26797"/>
  </joint>

  <link name="LHipRoll">
     <visual>
      <geometry>
        <mesh filename="meshes/LHipRoll_0.10.stl" scale="0.1 0.1 0.1"/>
      </geometry>
      <origin rpy="0 0 0" xyz="0 0.1255 0.0"/>
    </visual>
    <collision>
      <geometry>
        <mesh filename="meshes/LHipRoll_0.10.stl" scale="0.1 0.1 0.1"/>
      </geometry>
      <origin rpy="0 0 0" xyz="-0.036 0.1255 0.0"/>
    </collision>
  </link>

 
  <joint name="LHipPitch" type="revolute">
    <parent link="LHipRoll"/>
    <child link="LHipPitch"/>
    <origin rpy="0.0 0.0 0.0" xyz="0.0 -0.044 0.0"/>
    <axis xyz="1.0 0 0"/>
    <limit effort="1.329" lower="-1.5757" upper="1.5757" velocity="8.26797"/>
  </joint>

  <link name="LHipPitch">
     <visual>
      <geometry>
        <mesh filename="meshes/LHipPitch_0.10.stl" scale="0.1 0.1 0.1"/>
      </geometry>
      <origin rpy="0 0 0" xyz="-0.035 0.168 0.0"/>
    </visual>
    <collision>
      <geometry>
        <mesh filename="meshes/LHipPitch_0.10.stl" scale="0.1 0.1 0.1"/>
      </geometry>
      <origin rpy="0 0 0" xyz="-0.035 0.168 0.0"/>
    </collision>
  </link>

  <joint name="LKnee" type="revolute">
    <parent link="LHipPitch"/>
    <child link="LKnee"/>
    <origin rpy="0.0 0.0 0.0" xyz="0.0 -0.06 0.0"/>
    <axis xyz="1.0 0 0"/>
    <limit effort="1.329" lower="0.0" upper="1.5757" velocity="8.26797"/>
  </joint>

  <link name="LKnee">
     <visual>
      <geometry>
        <mesh filename="meshes/LKnee_0.10.stl" scale="0.1 0.1 0.1"/>
      </geometry>
      <origin rpy="0 0 0" xyz="-0.035 0.228 0.0"/>
    </visual>
    <collision>
      <geometry>
        <mesh filename="meshes/LKnee_0.10.stl" scale="0.1 0.1 0.1"/>
      </geometry>
      <origin rpy="0 0 0" xyz="-0.035 0.228 0.0"/>
    </collision>
  </link>

  <joint name="LAnklePitch" type="revolute">
    <parent link="LKnee"/>
    <child link="LAnklePitch"/>
    <origin rpy="0.0 0.0 0.0" xyz="0.0 0.0 0.0"/>
    <axis xyz="1.0 0 0"/>
    <limit effort="1.329" lower="-1.0" upper="1.0" velocity="8.26797"/>
  </joint>

  <link name="LAnklePitch">
     <visual>
      <geometry>
        <mesh filename="meshes/LAnklePitch_0.10.stl" scale="0.1 0.1 0.1"/>
      </geometry>
      <origin rpy="1.5757 0 1.5757" xyz="3 -31 0.0"/>
    </visual>
    <collision>
      <geometry>
        <mesh filename="meshes/LAnklePitch_0.10.stl" scale="0.1 0.1 0.1"/>
      </geometry>
      <origin rpy="1.5757 0 1.5757" xyz="0.0 -0.014 0.0"/>
    </collision>
  </link>
 
  <joint name="LAnkleRoll" type="revolute">
    <parent link="LAnklePitch"/>
    <child link="LAnkleRoll"/>
    <origin rpy="0.0 0.0 0.0" xyz="0.0 -0.035 0.0"/>
    <axis xyz="0 0 1.0"/>
    <limit effort="1.329" lower="-0.85" upper="0.45" velocity="8.26797"/>
  </joint>

  <link name="LAnkleRoll">
     <visual>
      <geometry>
        <mesh filename="meshes/LAnkleRoll_0.10.stl" scale="0.1 0.1 0.1"/>
      </geometry>
      <origin rpy="0.0 0 0.0" xyz="-0.035 0.33 0.008"/>
    </visual>
    <collision>
      <geometry>
        <mesh filename="meshes/LAnkleRoll_0.10.stl" scale="0.1 0.1 0.1"/>
      </geometry>
      <origin rpy="0 0 0" xyz="-0.035 0.33 0.008"/>
    </collision>
  </link>


  <joint name="RShoulderPitch" type="revolute">
    <parent link="torso"/>
    <child link="RShoulder"/>
    <origin rpy="0 0 0" xyz="-0.05 0.0 0.006"/>
    <axis xyz="1.0 0 0"/>
    <limit effort="1.329" lower="-3.1415" upper="1.0471" velocity="8.26797"/>
  </joint>

  <link name="RShoulder">
     <visual>
      <geometry>
        <mesh filename="meshes/RShoulderPitch_0.10.stl" scale="0.1 0.1 0.1"/>
      </geometry>
      <origin rpy="0 0 0" xyz="0.05 0 -0.006"/>
    </visual>
    <collision>
      <geometry>
        <mesh filename="meshes/RShoulderPitch_0.10.stl" scale="0.1 0.1 0.1"/>
      </geometry>
      <origin rpy="0 0 0" xyz="0.05 0 -0.006"/>
    </collision>
  </link>


  <joint name="RShoulderRoll" type="revolute">
    <parent link="RShoulder"/>
    <child link="RBicep"/>
    <origin rpy="0 0 0" xyz="-0.04 0.0 0.0"/>
    <axis xyz="0 0 1.0"/>
    <limit effort="1.329" lower="-1.5757" upper="1.5757" velocity="8.26797"/>
  </joint>

  <link name="RBicep">
     <visual>
      <geometry>
        <mesh filename="meshes/RShoulderRoll_0.10.stl" scale="0.1 0.1 0.1"/>
      </geometry>
      <origin rpy="0 0 0" xyz="0.09 0 -0.006"/>
    </visual>
    <collision>
      <geometry>
        <mesh filename="meshes/RShoulderRoll_0.10.stl" scale="0.1 0.1 0.1"/>
      </geometry>
      <origin rpy="0 0 0" xyz="0.09 0 -0.006"/>
    </collision>
  </link>

 <joint name="RElbowYaw" type="revolute">
    <parent link="RBicep"/>
    <child link="RElbow"/>
    <origin rpy="0 -1.575 3.14159" xyz="-0.075 0.0 0.0"/>
    <axis xyz="0 1.0 0"/>
    <limit effort="1.329" lower="-1.5757" upper="1.5757" velocity="8.26797"/>
  </joint>

  <link name="RElbow">
     <visual>
      <geometry>
        <mesh filename="meshes/RElbow_0.10.stl" scale="0.1 0.1 0.1"/>
      </geometry>
      <origin rpy="0 1.57 0" xyz="-5 0.0 0.135"/>
    </visual>
    <collision>
      <geometry>
        <mesh filename="meshes/RElbow_0.10.stl" scale="0.1 0.1 0.1"/>
      </geometry>
      <origin rpy="0 0 0" xyz="-0.0125 0.0 0.135"/>
    </collision>
  </link> 

  <joint name="RHipYaw" type="revolute">
    <parent link="torso"/>
    <child link="RHipYaw"/>
    <origin rpy="-1.5757 0.0 3.14159" xyz="-0.035 -0.035 0.0"/>
    <axis xyz="0 0 1.0"/>
    <limit effort="1.329" lower="-1.5757" upper="1.5757" velocity="8.26797"/>
  </joint>

  <link name="RHipYaw">
     <visual>
      <geometry>
        <mesh filename="meshes/RHipYaw_0.10.stl" scale="0.1 0.1 0.1"/>
      </geometry>
      <origin rpy="1.57 3.14 0" xyz="-4 -4 0"/>
    </visual>
    <collision>
      <geometry>
        <mesh filename="meshes/RHipYaw_0.10.stl" scale="0.1 0.1 0.1"/>
      </geometry>
      <origin rpy="0 0 0" xyz="0.0 0.0 0.0"/>
    </collision>
  </link>

  <joint name="RHipRoll" type="revolute">
    <parent link="RHipYaw"/>
    <child link="RHipRoll"/>
    <origin rpy="1.5757 3.14159 0.0" xyz="0.0 0.0 0.09"/>
    <axis xyz="0 0 1.0"/>
    <limit effort="1.329" lower="-1.5757" upper="0.45" velocity="8.26797"/>
  </joint>

  <link name="RHipRoll">
     <visual>
      <geometry>
        <mesh filename="meshes/RHipRoll_0.10.stl" scale="0.1 0.1 0.1"/>
      </geometry>
      <origin rpy="0 0 0" xyz="0.036 0.1255 0.0"/>
    </visual>
    <collision>
      <geometry>
        <mesh filename="meshes/RHipRoll_0.10.stl" scale="0.1 0.1 0.1"/>
      </geometry>
      <origin rpy="0 0 0" xyz="-0.036 0.1255 0.0"/>
    </collision>
  </link>
 
  <joint name="RHipPitch" type="revolute">
    <parent link="RHipRoll"/>
    <child link="RHipPitch"/>
    <origin rpy="0.0 0.0 0.0" xyz="0.0 -0.044 0.0"/>
    <axis xyz="1.0 0 0"/>
    <limit effort="1.329" lower="-1.5757" upper="1.5757" velocity="8.26797"/>
  </joint>

  <link name="RHipPitch">
     <visual>
      <geometry>
        <mesh filename="meshes/RHipPitch_0.10.stl" scale="0.1 0.1 0.1"/>
      </geometry>
      <origin rpy="0 0 0" xyz="0.035 0.168 0.0"/>
    </visual>
    <collision>
      <geometry>
        <mesh filename="meshes/RHipPitch_0.10.stl" scale="0.1 0.1 0.1"/>
      </geometry>
      <origin rpy="0 0 0" xyz="0.035 0.168 0.0"/>
    </collision>
  </link>

  <joint name="RKnee" type="revolute">
    <parent link="RHipPitch"/>
    <child link="RKnee"/>
    <origin rpy="0.0 0.0 0.0" xyz="0.0 -0.06 0.0"/>
    <axis xyz="1.0 0 0"/>
    <limit effort="1.329" lower="0.0" upper="1.5757" velocity="8.26797"/>
  </joint>

  <link name="RKnee">
     <visual>
      <geometry>
        <mesh filename="meshes/RKnee_0.10.stl" scale="0.1 0.1 0.1"/>
      </geometry>
      <origin rpy="0 0 0" xyz="0.035 0.228 0.0"/>
    </visual>
    <collision>
      <geometry>
        <mesh filename="meshes/RKnee_0.10.stl" scale="0.1 0.1 0.1"/>
      </geometry>
      <origin rpy="0 0 0" xyz="0.035 0.228 0.0"/>
    </collision>
  </link>

  <joint name="RAnklePitch" type="revolute">
    <parent link="RKnee"/>
    <child link="RAnklePitch"/>
    <origin rpy="0.0 0.0 0.0" xyz="0.0 -0.065 -0.008"/>
    <axis xyz="1.0 0 0"/>
    <limit effort="1.329" lower="-1.0" upper="1.0" velocity="8.26797"/>
  </joint>

  <link name="RAnklePitch">
     <visual>
      <geometry>
        <mesh filename="meshes/RAnklePitch_0.10.stl" scale="0.1 0.1 0.1"/>
      </geometry>
      <origin rpy="1.5757 0 1.5757" xyz="-3 -31 0.0"/>
    </visual>
    <collision>
      <geometry>
        <mesh filename="meshes/RAnklePitch_0.10.stl" scale="0.1 0.1 0.1"/>
      </geometry>
      <origin rpy="1.5757 0 1.5757" xyz="0.0 -0.014 0.0"/>
    </collision>
  </link>
 
  <joint name="RAnkleRoll" type="revolute">
    <parent link="RAnklePitch"/>
    <child link="RAnkleRoll"/>
    <origin rpy="0.0 0.0 0.0" xyz="0.0 -0.035 0.0"/>
    <axis xyz="0 0 1.0"/>
    <limit effort="1.329" lower="-0.85" upper="0.45" velocity="8.26797"/>
  </joint>

  <link name="RAnkleRoll">
     <visual>
      <geometry>
        <mesh filename="meshes/RAnkleRoll_0.10.stl" scale="0.1 0.1 0.1"/>
      </geometry>
      <origin rpy="0.0 0 0.0" xyz="0.035 0.33 0.008"/>
    </visual>
    <collision>
      <geometry>
        <mesh filename="meshes/RAnkleRoll_0.10.stl" scale="0.1 0.1 0.1"/>
      </geometry>
      <origin rpy="0 0 0" xyz="0.035 0.33 0.008"/>
    </collision>
  </link>  

</robot>
